Workbook

Sheet DATASET A
A1: BOOKING NUMBER | B1: DEPARTURE DATE | C1: ROUTE | D1: CLASIFICATION | E1: AIRLINE | F1: INTIAL FARE | G1: ACTUAL FARE | H1: CATEGORY | I1: RESOLUTION TYPE
A2: 1394729381 | B2: 46360 | C2: TPE-MEL | D2: International | E2: AK | F2: 1155000 | G2: 1328250 | H2: =IFS(G28<=F28, "Normal", G28<=(F28*2), "Fare Increase", TRUE, "Over Buffer") -> Normal | I2: =IFS(OR(H2="Fare Increase", H2="Normal"), "Issued", H2="Over Buffer", "Refund", H2="Refund", "N/A") -> Issued
A3: 1360743921 | B3: 46256 | C3: DMK-CNX | D3: Domestic | E3: DD | F3: 2034000 | G3: 2847600 | H3: =IFS(G29<=F29, "Normal", G29<=(F29*2), "Fare Increase", TRUE, "Over Buffer") -> Over Buffer | I3: =IFS(OR(H3="Fare Increase", H3="Normal"), "Issued", H3="Over Buffer", "Refund", H3="Refund", "N/A") -> Refund
A4: 1324193207 | B4: 46124 | C4: SIN-CGK | D4: International | E4: JT | F4: 820000 | G4: 1148000 | H4: =IFS(G30<=F30, "Normal", G30<=(F30*2), "Fare Increase", TRUE, "Over Buffer") -> Fare Increase | I4: =IFS(OR(H4="Fare Increase", H4="Normal"), "Issued", H4="Over Buffer", "Refund", H4="Refund", "N/A") -> Issued
A5: 1343650044 | B5: 46148 | C5: TPE-MEL | D5: International | E5: TR | F5: 13901000 | G5: 15986150 | H5: =IFS(G31<=F31, "Normal", G31<=(F31*2), "Fare Increase", TRUE, "Over Buffer") -> Normal | I5: =IFS(OR(H5="Fare Increase", H5="Normal"), "Issued", H5="Over Buffer", "Refund", H5="Refund", "N/A") -> Issued
A6: 1329726387 | B6: 46239 | C6: CGK-DPS | D6: Domestic | E6: JT | F6: 4195000 | G6: 4824250 | H6: =IFS(G32<=F32, "Normal", G32<=(F32*2), "Fare Increase", TRUE, "Over Buffer") -> Fare Increase | I6: =IFS(OR(H6="Fare Increase", H6="Normal"), "Issued", H6="Over Buffer", "Refund", H6="Refund", "N/A") -> Issued
A7: 1385334759 | B7: 46079 | C7: SGN-HAN | D7: Domestic | E7: VZ | F7: 1635000 | G7: 2289000 | H7: =IFS(G33<=F33, "Normal", G33<=(F33*2), "Fare Increase", TRUE, "Over Buffer") -> Normal | I7: =IFS(OR(H7="Fare Increase", H7="Normal"), "Issued", H7="Over Buffer", "Refund", H7="Refund", "N/A") -> Issued
A8: 1351860028 | B8: 46140 | C8: TPE-MEL | D8: International | E8: JT | F8: 927000 | G8: 1297800 | H8: =IFS(G34<=F34, "Normal", G34<=(F34*2), "Fare Increase", TRUE, "Over Buffer") -> Normal | I8: =IFS(OR(H8="Fare Increase", H8="Normal"), "Issued", H8="Over Buffer", "Refund", H8="Refund", "N/A") -> Issued
A9: 1324359029 | B9: 46283 | C9: TPE-MEL | D9: International | E9: AK | F9: 1705000 | G9: 1619750 | H9: =IFS(G35<=F35, "Normal", G35<=(F35*2), "Fare Increase", TRUE, "Over Buffer") -> Normal | I9: =IFS(OR(H9="Fare Increase", H9="Normal"), "Issued", H9="Over Buffer", "Refund", H9="Refund", "N/A") -> Issued
A10: 1382513538 | B10: 46091 | C10: SUB-SOQ | D10: Domestic | E10: QG | F10: 1379000 | G10: 1310050 | H10: =IFS(G36<=F36, "Normal", G36<=(F36*2), "Fare Increase", TRUE, "Over Buffer") -> Over Buffer | I10: =IFS(OR(H10="Fare Increase", H10="Normal"), "Issued", H10="Over Buffer", "Refund", H10="Refund", "N/A") -> Refund
A11: 1321455662 | B11: 46384 | C11: CGK-DPS | D11: Domestic | E11: GA | F11: 9500000 | G11: 23750000 | H11: =IFS(G37<=F37, "Normal", G37<=(F37*2), "Fare Increase", TRUE, "Over Buffer") -> Over Buffer | I11: =IFS(OR(H11="Fare Increase", H11="Normal"), "Issued", H11="Over Buffer", "Refund", H11="Refund", "N/A") -> Refund
A12: 1317152879 | B12: 46162 | C12: TPE-MEL | D12: International | E12: ID | F12: 8587000 | G12: 9875050 | H12: =IFS(G38<=F38, "Normal", G38<=(F38*2), "Fare Increase", TRUE, "Over Buffer") -> Over Buffer | I12: =IFS(OR(H12="Fare Increase", H12="Normal"), "Issued", H12="Over Buffer", "Refund", H12="Refund", "N/A") -> Refund
A13: 1397026610 | B13: 46380 | C13: DMK-CNX | D13: Domestic | E13: OD | F13: 7828000 | G13: 9002200 | H13: =IFS(G39<=F39, "Normal", G39<=(F39*2), "Fare Increase", TRUE, "Over Buffer") -> Normal | I13: =IFS(OR(H13="Fare Increase", H13="Normal"), "Issued", H13="Over Buffer", "Refund", H13="Refund", "N/A") -> Issued
... A551: 1322328771 | B551: 46156 | C551: SUB-SOQ | D551: Domestic | E551: XJ | F551: 3423000 | G551: 3251850 | H551: =IFS(G577<=F577, "Normal", G577<=(F577*2), "Fare Increase", TRUE, "Over Buffer") -> Normal | I551: =IFS(OR(H551="Fare Increase", H551="Normal"), "Issued", H551="Over Buffer", "Refund", H551="Refund", "N/A") -> Issued

Sheet DATASET EDIT
A1: BOOKING NUMBER | B1: DEPARTURE DATE | C1: MONTH TREND | D1: ROUTE | E1: CLASIFICATION | F1: AIRLINE | G1: AIRLINE GROUPING | H1: INTIAL FARE | I1: ACTUAL FARE | J1: FARE DIFFERENT | K1: MARK UP | L1: CATEGORY | M1: COST OF REFUND | N1: RESOLUTION TYPE | O1: LOSS/PROFIT | P1: Cat Flag | Q1: Loss / Profit Flag | R1: Refund Flag
A2: 1394729381 | B2: 46360 | C2: =TEXT(B2,"mmmm") -> December | D2: TPE-MEL | E2: International | F2: AK | G2: =VLOOKUP(F2, 'KODE PESAWAT'!$A$2:$C$42, 3, FALSE) -> AirAsia Group | H2: 1155000 | I2: 1328250 | J2: =H2-I2 -> -173250 | K2: =(H2-I2)/H2 -> -0.15 | L2: =IFS(I2<=H2, "Normal", I2<=(H2*2), "Fare Increase", TRUE, "Over Buffer") -> Fare Increase | M2: =IF(L2="OVER BUFFER",-H2,I2-H2) -> 173250 | N2: =IFS(OR(L2="Fare Increase", L2="Normal"), "Issued", L2="Over Buffer", "Refund", L2="Refund", "N/A") -> Issued | O2: =IFS(L2="OVER BUFFER","N/A",L2="FARE INCREASE","LOSS",L2="NORMAL","PROFIT",1,0) -> LOSS | P2: =IF(N2="ISSUED",1,0) -> 1 | Q2: =IF(O2="PROFIT",1,0) -> 0 | R2: =IF(N2="REFUND",1,0) -> 0
A3: 1360743921 | B3: 46256 | C3: =TEXT(B3,"mmmm") -> August | D3: DMK-CNX | E3: Domestic | F3: DD | G3: =VLOOKUP(F3, 'KODE PESAWAT'!$A$2:$C$42, 3, FALSE) -> Thai Airways Group (Associate) | H3: 2034000 | I3: 2847600 | J3: =H3-I3 -> -813600 | K3: =(H3-I3)/H3 -> -0.4 | L3: =IFS(I3<=H3, "Normal", I3<=(H3*2), "Fare Increase", TRUE, "Over Buffer") -> Fare Increase | M3: =IF(L3="OVER BUFFER",-H3,I3-H3) -> 813600 | N3: =IFS(OR(L3="Fare Increase", L3="Normal"), "Issued", L3="Over Buffer", "Refund", L3="Refund", "N/A") -> Issued | O3: =IFS(L3="OVER BUFFER","N/A",L3="FARE INCREASE","LOSS",L3="NORMAL","PROFIT",1,0) -> LOSS | P3: =IF(N3="ISSUED",1,0) -> 1 | Q3: =IF(O3="PROFIT",1,0) -> 0 | R3: =IF(N3="REFUND",1,0) -> 0
A4: 1324193207 | B4: 46124 | C4: =TEXT(B4,"mmmm") -> April | D4: SIN-CGK | E4: International | F4: JT | G4: =VLOOKUP(F4, 'KODE PESAWAT'!$A$2:$C$42, 3, FALSE) -> Lion Air Group | H4: 820000 | I4: 1148000 | J4: =H4-I4 -> -328000 | K4: =(H4-I4)/H4 -> -0.4 | L4: =IFS(I4<=H4, "Normal", I4<=(H4*2), "Fare Increase", TRUE, "Over Buffer") -> Fare Increase | M4: =IF(L4="OVER BUFFER",-H4,I4-H4) -> 328000 | N4: =IFS(OR(L4="Fare Increase", L4="Normal"), "Issued", L4="Over Buffer", "Refund", L4="Refund", "N/A") -> Issued | O4: =IFS(L4="OVER BUFFER","N/A",L4="FARE INCREASE","LOSS",L4="NORMAL","PROFIT",1,0) -> LOSS | P4: =IF(N4="ISSUED",1,0) -> 1 | Q4: =IF(O4="PROFIT",1,0) -> 0 | R4: =IF(N4="REFUND",1,0) -> 0
A5: 1343650044 | B5: 46148 | C5: =TEXT(B5,"mmmm") -> May | D5: TPE-MEL | E5: International | F5: TR | G5: =VLOOKUP(F5, 'KODE PESAWAT'!$A$2:$C$42, 3, FALSE) -> Singapore Airlines Group | H5: 13901000 | I5: 15986150 | J5: =H5-I5 -> -2085150 | K5: =(H5-I5)/H5 -> -0.15 | L5: =IFS(I5<=H5, "Normal", I5<=(H5*2), "Fare Increase", TRUE, "Over Buffer") -> Fare Increase | M5: =IF(L5="OVER BUFFER",-H5,I5-H5) -> 2085150 | N5: =IFS(OR(L5="Fare Increase", L5="Normal"), "Issued", L5="Over Buffer", "Refund", L5="Refund", "N/A") -> Issued | O5: =IFS(L5="OVER BUFFER","N/A",L5="FARE INCREASE","LOSS",L5="NORMAL","PROFIT",1,0) -> LOSS | P5: =IF(N5="ISSUED",1,0) -> 1 | Q5: =IF(O5="PROFIT",1,0) -> 0 | R5: =IF(N5="REFUND",1,0) -> 0
A6: 1329726387 | B6: 46239 | C6: =TEXT(B6,"mmmm") -> August | D6: CGK-DPS | E6: Domestic | F6: JT | G6: =VLOOKUP(F6, 'KODE PESAWAT'!$A$2:$C$42, 3, FALSE) -> Lion Air Group | H6: 4195000 | I6: 4824250 | J6: =H6-I6 -> -629250 | K6: =(H6-I6)/H6 -> -0.15 | L6: =IFS(I6<=H6, "Normal", I6<=(H6*2), "Fare Increase", TRUE, "Over Buffer") -> Fare Increase | M6: =IF(L6="OVER BUFFER",-H6,I6-H6) -> 629250 | N6: =IFS(OR(L6="Fare Increase", L6="Normal"), "Issued", L6="Over Buffer", "Refund", L6="Refund", "N/A") -> Issued | O6: =IFS(L6="OVER BUFFER","N/A",L6="FARE INCREASE","LOSS",L6="NORMAL","PROFIT",1,0) -> LOSS | P6: =IF(N6="ISSUED",1,0) -> 1 | Q6: =IF(O6="PROFIT",1,0) -> 0 | R6: =IF(N6="REFUND",1,0) -> 0
A7: 1385334759 | B7: 46079 | C7: =TEXT(B7,"mmmm") -> February | D7: SGN-HAN | E7: Domestic | F7: VZ | G7: =VLOOKUP(F7, 'KODE PESAWAT'!$A$2:$C$42, 3, FALSE) -> VietJet Group | H7: 1635000 | I7: 2289000 | J7: =H7-I7 -> -654000 | K7: =(H7-I7)/H7 -> -0.4 | L7: =IFS(I7<=H7, "Normal", I7<=(H7*2), "Fare Increase", TRUE, "Over Buffer") -> Fare Increase | M7: =IF(L7="OVER BUFFER",-H7,I7-H7) -> 654000 | N7: =IFS(OR(L7="Fare Increase", L7="Normal"), "Issued", L7="Over Buffer", "Refund", L7="Refund", "N/A") -> Issued | O7: =IFS(L7="OVER BUFFER","N/A",L7="FARE INCREASE","LOSS",L7="NORMAL","PROFIT",1,0) -> LOSS | P7: =IF(N7="ISSUED",1,0) -> 1 | Q7: =IF(O7="PROFIT",1,0) -> 0 | R7: =IF(N7="REFUND",1,0) -> 0
A8: 1351860028 | B8: 46140 | C8: =TEXT(B8,"mmmm") -> April | D8: TPE-MEL | E8: International | F8: JT | G8: =VLOOKUP(F8, 'KODE PESAWAT'!$A$2:$C$42, 3, FALSE) -> Lion Air Group | H8: 927000 | I8: 1297800 | J8: =H8-I8 -> -370800 | K8: =(H8-I8)/H8 -> -0.4 | L8: =IFS(I8<=H8, "Normal", I8<=(H8*2), "Fare Increase", TRUE, "Over Buffer") -> Fare Increase | M8: =IF(L8="OVER BUFFER",-H8,I8-H8) -> 370800 | N8: =IFS(OR(L8="Fare Increase", L8="Normal"), "Issued", L8="Over Buffer", "Refund", L8="Refund", "N/A") -> Issued | O8: =IFS(L8="OVER BUFFER","N/A",L8="FARE INCREASE","LOSS",L8="NORMAL","PROFIT",1,0) -> LOSS | P8: =IF(N8="ISSUED",1,0) -> 1 | Q8: =IF(O8="PROFIT",1,0) -> 0 | R8: =IF(N8="REFUND",1,0) -> 0
A9: 1324359029 | B9: 46283 | C9: =TEXT(B9,"mmmm") -> September | D9: TPE-MEL | E9: International | F9: AK | G9: =VLOOKUP(F9, 'KODE PESAWAT'!$A$2:$C$42, 3, FALSE) -> AirAsia Group | H9: 1705000 | I9: 1619750 | J9: =H9-I9 -> 85250 | K9: =(H9-I9)/H9 -> 0.05 | L9: =IFS(I9<=H9, "Normal", I9<=(H9*2), "Fare Increase", TRUE, "Over Buffer") -> Normal | M9: =IF(L9="OVER BUFFER",-H9,I9-H9) -> -85250 | N9: =IFS(OR(L9="Fare Increase", L9="Normal"), "Issued", L9="Over Buffer", "Refund", L9="Refund", "N/A") -> Issued | O9: =IFS(L9="OVER BUFFER","N/A",L9="FARE INCREASE","LOSS",L9="NORMAL","PROFIT",1,0) -> PROFIT | P9: =IF(N9="ISSUED",1,0) -> 1 | Q9: =IF(O9="PROFIT",1,0) -> 1 | R9: =IF(N9="REFUND",1,0) -> 0
A10: 1382513538 | B10: 46091 | C10: =TEXT(B10,"mmmm") -> March | D10: SUB-SOQ | E10: Domestic | F10: QG | G10: =VLOOKUP(F10, 'KODE PESAWAT'!$A$2:$C$42, 3, FALSE) -> Garuda Indonesia Group | H10: 1379000 | I10: 1310050 | J10: =H10-I10 -> 68950 | K10: =(H10-I10)/H10 -> 0.05 | L10: =IFS(I10<=H10, "Normal", I10<=(H10*2), "Fare Increase", TRUE, "Over Buffer") -> Normal | M10: =IF(L10="OVER BUFFER",-H10,I10-H10) -> -68950 | N10: =IFS(OR(L10="Fare Increase", L10="Normal"), "Issued", L10="Over Buffer", "Refund", L10="Refund", "N/A") -> Issued | O10: =IFS(L10="OVER BUFFER","N/A",L10="FARE INCREASE","LOSS",L10="NORMAL","PROFIT",1,0) -> PROFIT | P10: =IF(N10="ISSUED",1,0) -> 1 | Q10: =IF(O10="PROFIT",1,0) -> 1 | R10: =IF(N10="REFUND",1,0) -> 0
A11: 1321455662 | B11: 46384 | C11: =TEXT(B11,"mmmm") -> December | D11: CGK-DPS | E11: Domestic | F11: GA | G11: =VLOOKUP(F11, 'KODE PESAWAT'!$A$2:$C$42, 3, FALSE) -> Garuda Indonesia Group | H11: 9500000 | I11: 23750000 | J11: =H11-I11 -> -14250000 | K11: =(H11-I11)/H11 -> -1.5 | L11: =IFS(I11<=H11, "Normal", I11<=(H11*2), "Fare Increase", TRUE, "Over Buffer") -> Over Buffer | M11: =IF(L11="OVER BUFFER",-H11,I11-H11) -> -9500000 | N11: =IFS(OR(L11="Fare Increase", L11="Normal"), "Issued", L11="Over Buffer", "Refund", L11="Refund", "N/A") -> Refund | O11: =IFS(L11="OVER BUFFER","N/A",L11="FARE INCREASE","LOSS",L11="NORMAL","PROFIT",1,0) -> N/A | P11: =IF(N11="ISSUED",1,0) -> 0 | Q11: =IF(O11="PROFIT",1,0) -> 0 | R11: =IF(N11="REFUND",1,0) -> 1
A12: 1317152879 | B12: 46162 | C12: =TEXT(B12,"mmmm") -> May | D12: TPE-MEL | E12: International | F12: ID | G12: =VLOOKUP(F12, 'KODE PESAWAT'!$A$2:$C$42, 3, FALSE) -> Lion Air Group | H12: 8587000 | I12: 9875050 | J12: =H12-I12 -> -1288050 | K12: =(H12-I12)/H12 -> -0.15 | L12: =IFS(I12<=H12, "Normal", I12<=(H12*2), "Fare Increase", TRUE, "Over Buffer") -> Fare Increase | M12: =IF(L12="OVER BUFFER",-H12,I12-H12) -> 1288050 | N12: =IFS(OR(L12="Fare Increase", L12="Normal"), "Issued", L12="Over Buffer", "Refund", L12="Refund", "N/A") -> Issued | O12: =IFS(L12="OVER BUFFER","N/A",L12="FARE INCREASE","LOSS",L12="NORMAL","PROFIT",1,0) -> LOSS | P12: =IF(N12="ISSUED",1,0) -> 1 | Q12: =IF(O12="PROFIT",1,0) -> 0 | R12: =IF(N12="REFUND",1,0) -> 0
A13: 1397026610 | B13: 46380 | C13: =TEXT(B13,"mmmm") -> December | D13: DMK-CNX | E13: Domestic | F13: OD | G13: =VLOOKUP(F13, 'KODE PESAWAT'!$A$2:$C$42, 3, FALSE) -> Lion Air Group | H13: 7828000 | I13: 9002200 | J13: =H13-I13 -> -1174200 | K13: =(H13-I13)/H13 -> -0.15 | L13: =IFS(I13<=H13, "Normal", I13<=(H13*2), "Fare Increase", TRUE, "Over Buffer") -> Fare Increase | M13: =IF(L13="OVER BUFFER",-H13,I13-H13) -> 1174200 | N13: =IFS(OR(L13="Fare Increase", L13="Normal"), "Issued", L13="Over Buffer", "Refund", L13="Refund", "N/A") -> Issued | O13: =IFS(L13="OVER BUFFER","N/A",L13="FARE INCREASE","LOSS",L13="NORMAL","PROFIT",1,0) -> LOSS | P13: =IF(N13="ISSUED",1,0) -> 1 | Q13: =IF(O13="PROFIT",1,0) -> 0 | R13: =IF(N13="REFUND",1,0) -> 0
... A551: 1322328771 | B551: 46156 | C551: =TEXT(B551,"mmmm") -> May | D551: SUB-SOQ | E551: Domestic | F551: XJ | G551: =VLOOKUP(F551, 'KODE PESAWAT'!$A$2:$C$42, 3, FALSE) -> AirAsia Group | H551: 3423000 | I551: 3251850 | J551: =H551-I551 -> 171150 | K551: =(H551-I551)/H551 -> 0.05 | L551: =IFS(I551<=H551, "Normal", I551<=(H551*2), "Fare Increase", TRUE, "Over Buffer") -> Normal | M551: =IF(L551="OVER BUFFER",-H551,I551-H551) -> -171150 | N551: =IFS(OR(L551="Fare Increase", L551="Normal"), "Issued", L551="Over Buffer", "Refund", L551="Refund", "N/A") -> Issued | O551: =IFS(L551="OVER BUFFER","N/A",L551="FARE INCREASE","LOSS",L551="NORMAL","PROFIT",1,0) -> PROFIT | P551: =IF(N551="ISSUED",1,0) -> 1 | Q551: =IF(O551="PROFIT",1,0) -> 1 | R551: =IF(N551="REFUND",1,0) -> 0

Sheet Pivot Table 1

Sheet DASHBOARD
A3: A. Profit & Loss Analysis
A5: 1. Total Revenue vs. Total Loss | G5: From the chart, it can be seen that baggage sales in 2025 will still face high losses with a percentage value of 43.78%. This should be a concern and a suitable solution should be found immediately so that the percentage of losses can be reduced.
A13: 2. Loss Analysis by Airline
A15: AIRLINE | B15: TOTAL AMOUNT | C15: % | E15: =IFERROR(__xludf.DUMMYFUNCTION("QUERY('DATASET EDIT'!A:R, ""SELECT F, SUM(I) WHERE F IS NOT NULL AND O = 'LOSS' GROUP BY F ORDER BY SUM(I) DESC LIMIT 5 LABEL F 'Airline', SUM(I) 'Total Loss Amount (Rp)'"",1) "),"Airline") -> Airline | F15: =IFERROR(__xludf.DUMMYFUNCTION("""COMPUTED_VALUE"""),"Total Loss Amount (Rp)") -> Total Loss Amount (Rp)
A16: SL | B16: 219635300 | C16: 0.17964473 | E16: =IFERROR(__xludf.DUMMYFUNCTION("""COMPUTED_VALUE"""),"SL") -> SL | F16: =IFERROR(__xludf.DUMMYFUNCTION("""COMPUTED_VALUE"""),2.196353E8) -> 219635300
A17: JT | B17: 136981000 | C17: 0.11203989 | E17: =IFERROR(__xludf.DUMMYFUNCTION("""COMPUTED_VALUE"""),"JT") -> JT | F17: =IFERROR(__xludf.DUMMYFUNCTION("""COMPUTED_VALUE"""),1.36981E8) -> 136981000
A18: VN | B18: 100634500 | C18: 0.082311257 | E18: =IFERROR(__xludf.DUMMYFUNCTION("""COMPUTED_VALUE"""),"VN") -> VN | F18: =IFERROR(__xludf.DUMMYFUNCTION("""COMPUTED_VALUE"""),1.006345E8) -> 100634500
A19: AK | B19: 97936150 | C19: 0.080104215 | E19: =IFERROR(__xludf.DUMMYFUNCTION("""COMPUTED_VALUE"""),"AK") -> AK | F19: =IFERROR(__xludf.DUMMYFUNCTION("""COMPUTED_VALUE"""),9.793615E7) -> 97936150
A20: GA | B20: 94570050 | C20: 0.077351005 | E20: =IFERROR(__xludf.DUMMYFUNCTION("""COMPUTED_VALUE"""),"GA") -> GA | F20: =IFERROR(__xludf.DUMMYFUNCTION("""COMPUTED_VALUE"""),9.457005E7) -> 94570050
A21: QG | B21: 81204850 | C21: 0.066419302
A22: ID | B22: 78006500 | C22: 0.063803299
A23: OD | B23: 76886650 | C23: 0.062887348
A24: DD | B24: 62441600 | C24: 0.051072411
A25: VU | B25: 61096400 | C25: 0.049972142
A26: TR | B26: 52951950 | C26: 0.04331061
A27: 5J | B27: 44058700 | C27: 0.036036617
A28: VZ | B28: 29592700 | C28: 0.024204545
A29: D7 | B29: 23138500 | C29: 0.018925508
A30: QZ | B30: 20811150 | C30: 0.017021915
A31: VJ | B31: 18313350 | C31: 0.014978907
A32: VA | B32: 10430000 | C32: 0.0085309353
... A38: Grand Total | B38: 1222609200 | C38: 1
A40: 3. Impact of Fare Difference
A42: LOSS/PROFIT | B42: INITIAL FARE | C42: ACTUAL FARE | D42: CASH IMPACT | E42: Calculated Field 1
A43: LOSS | B43: 958373000 | C43: 1222609200 | D43: 264236200 | E43: 1222609200
A44: N/A | B44: 433320000 | C44: 1083300000 | D44: -433320000 | E44: 0
A45: PROFIT | B45: 512504000 | C45: 486878800 | D45: -25625200 | E45: 486878800
A46: Grand Total | B46: 1904197000 | C46: 2792788000 | D46: -194709000 | E46: 1709488000
L48: dari chart ini kita dapat melihat jika ada ketimpangan antara total booking dan jumlah total actual yang mana pada bulan angustus memiliki total loss -Rp29,625,400.00 sedangkan dibulan desember dengan total yang lebih banyak mengalami loss yang lebih sedikit yaitu -Rp14,635,950.00. Hal ini dapat mendemostrasikan bahwa volume booking yang tinggi belum tentu menjadi root cause dari tingginya kerugian.
A64: B. Market Share & Performance
A66: 1. Top 5 Airlines by Volume
A68: =IFERROR(__xludf.DUMMYFUNCTION("QUERY('DATASET EDIT'!F2:F1001, ""select F, count(F) where F is not null group by F order by count(F) desc limit 5 label F 'Airline', count(F) 'Total Transactions'"") "),"Airline") -> Airline | B68: =IFERROR(__xludf.DUMMYFUNCTION("""COMPUTED_VALUE"""),"Total Transactions") -> Total Transactions
A69: =IFERROR(__xludf.DUMMYFUNCTION("""COMPUTED_VALUE"""),"JT") -> JT | B69: =IFERROR(__xludf.DUMMYFUNCTION("""COMPUTED_VALUE"""),79.0) -> 79
A70: =IFERROR(__xludf.DUMMYFUNCTION("""COMPUTED_VALUE"""),"SL") -> SL | B70: =IFERROR(__xludf.DUMMYFUNCTION("""COMPUTED_VALUE"""),72.0) -> 72
A71: =IFERROR(__xludf.DUMMYFUNCTION("""COMPUTED_VALUE"""),"AK") -> AK | B71: =IFERROR(__xludf.DUMMYFUNCTION("""COMPUTED_VALUE"""),43.0) -> 43
A72: =IFERROR(__xludf.DUMMYFUNCTION("""COMPUTED_VALUE"""),"ID") -> ID | B72: =IFERROR(__xludf.DUMMYFUNCTION("""COMPUTED_VALUE"""),39.0) -> 39
A73: =IFERROR(__xludf.DUMMYFUNCTION("""COMPUTED_VALUE"""),"DD") -> DD | B73: =IFERROR(__xludf.DUMMYFUNCTION("""COMPUTED_VALUE"""),38.0) -> 38
A75: 2. Top 5 Most Popular Routes
A76: =IFERROR(__xludf.DUMMYFUNCTION("QUERY('DATASET EDIT'!D2:D1001, ""select D, count(D) where D is not null group by D order by count(D) desc limit 5 label D 'Route', count(D) 'Total Transactions'"") "),"Route") -> Route | B76: =IFERROR(__xludf.DUMMYFUNCTION("""COMPUTED_VALUE"""),"Total Transactions") -> Total Transactions
A77: =IFERROR(__xludf.DUMMYFUNCTION("""COMPUTED_VALUE"""),"DMK-CNX") -> DMK-CNX | B77: =IFERROR(__xludf.DUMMYFUNCTION("""COMPUTED_VALUE"""),106.0) -> 106
...

Sheet KODE BANDARA
A1: Kode IATA | B1: Kota | C1: Negara | D1: Kode Negara
A2: AAP | B2: Samarinda | C2: Indonesia | D2: ID
A3: ADL | B3: Adelaide | C3: Australia | D3: AU
A4: AKL | B4: Auckland | C4: Selandia Baru | D4: NZ
A5: ALA | B5: Almaty | C5: Kazakhstan | D5: KZ
A6: AMD | B6: Ahmedabad | C6: India | D6: IN
A7: AMQ | B7: Ambon | C7: Indonesia | D7: ID
A8: AOR | B8: Alor Setar | C8: Malaysia | D8: MY
A9: ATH | B9: Athena | C9: Yunani | D9: GR
A10: ATQ | B10: Amritsar | C10: India | D10: IN
A11: BCD | B11: Bacolod | C11: Filipina | D11: PH
A12: BDJ | B12: Banjarmasin | C12: Indonesia | D12: ID
... A240: HYD | B240: Rajiv Gandhi International Airport | C240: India | D240: IN

Sheet KODE PESAWAT
A1: Kode IATA | B1: Nama Maskapai | C1: Airline Grouping
A2: JT | B2: Lion Air | C2: Lion Air Group
A3: ID | B3: Batik Air | C3: Lion Air Group
A4: OD | B4: Batik Air Malaysia | C4: Lion Air Group
A5: SL | B5: Thai Lion Air | C5: Lion Air Group
A6: IW | B6: Wings Air | C6: Lion Air Group
A7: AK | B7: AirAsia (Malaysia) | C7: AirAsia Group
A8: QZ | B8: Indonesia AirAsia | C8: AirAsia Group
A9: FD | B9: Thai AirAsia | C9: AirAsia Group
A10: Z2 | B10: Philippines AirAsia | C10: AirAsia Group
A11: GA | B11: Garuda Indonesia | C11: Garuda Indonesia Group
A12: QG | B12: Citilink | C12: Garuda Indonesia Group
... A42: F3 | B42: Flyadeal | C42: Saudi Arabian Airlines (Saudia) Group
